Workbook

Sheet Chart_Workload
A3: Row Labels | B3: Count of Patient_ID
A4: Biochemistry | B4: 30
A5: Hematology | B5: 15
A6: Microbiology | B6: 89
A7: Molecular | B7: 15
A8: Grand Total | B8: 149

Sheet Chart_TAT_Gap
A3: Row Labels | B3: Min_TAT | C3: Max_TAT
A4: Biochemistry | B4: 3 | C4: 48
A5: Hematology | B5: 3 | C5: 52
A6: Microbiology | B6: 2 | C6: 52
A7: Molecular | B7: 3 | C7: 43
A8: Grand Total | B8: 2 | C8: 52

Sheet Chart_Urgency_Share
A3: Count of Patient_ID | B3: Column Labels
A4: Row Labels | B4: Delayed | C4: On-Time | D4: Grand Total
A5: Routine | B5: 23 | C5: 52 | D5: 75
A6: Stat | B6: 15 | C6: 59 | D6: 74
A7: Grand Total | B7: 38 | C7: 111 | D7: 149

Sheet Chart_Sample_TAT
A3: Row Labels | B3: Average of Actual_TAT_Hours
A4: EDTA Blood | B4: 25.6
A5: Sputum | B5: 23.133333
A6: Serum | B6: 21.033333
A7: CSF Fluid | B7: 20.4
A8: Whole Blood | B8: 19.6
A9: Nasopharyngeal Swab | B9: 19.133333
A10: Stool | B10: 18.333333
A11: Pus Swab | B11: 17.785714
A12: Urine | B12: 17.533333
A13: Grand Total | B13: 20.375839

Sheet Lab_Diagnostics_TAT_Project
A1: Patient_ID | B1: Test_Name | C1: Department | D1: Urgency | E1: Sample_Type | F1: Actual_TAT_Hours | G1: Target_TAT | H1: Status | I1: Data_Quality_ID | J1: Data_Error_Check
A2: P-2026-01 | B2: Blood Culture and Sensitivity | C2: Microbiology | D2: Stat | E2: Whole Blood | F2: 36 | G2: =VLOOKUP(C2,Master_Targets!$A$2:$B$5,2,0) -> 48 | H2: =IF(F2>G2,"Delayed","On-Time") -> On-Time | I2: =IF(COUNTIF($A$2:$A$150,A2)>1,"Duplicate","Unique") -> Unique | J2: =IF(OR(F2<=0,F2>100),"Error:Check Data","Valid") -> Valid
A3: P-2026-02 | B3: Urine Culture | C3: Microbiology | D3: Routine | E3: Urine | F3: 48 | G3: =VLOOKUP(C3,Master_Targets!$A$2:$B$5,2,0) -> 48 | H3: =IF(F3>G3,"Delayed","On-Time") -> On-Time | I3: =IF(COUNTIF($A$2:$A$150,A3)>1,"Duplicate","Unique") -> Unique | J3: =IF(OR(F2<=0,F3>100),"Error:Check Data","Valid") -> Valid
A4: P-2026-03 | B4: CBC (Complete Blod Count) | C4: Hematology | D4: Routine | E4: EDTA Blood | F4: 4 | G4: =VLOOKUP(C4,Master_Targets!$A$2:$B$5,2,0) -> 4 | H4: =IF(F4>G4,"Delayed","On-Time") -> On-Time | I4: =IF(COUNTIF($A$2:$A$150,A4)>1,"Duplicate","Unique") -> Unique | J4: =IF(OR(F4<=0,F4>100),"Error:Check Data","Valid") -> Valid
A5: P-2026-04 | B5: Sputum For AFB | C5: Microbiology | D5: Routine | E5: Sputum | F5: 24 | G5: =VLOOKUP(C5,Master_Targets!$A$2:$B$5,2,0) -> 48 | H5: =IF(F5>G5,"Delayed","On-Time") -> On-Time | I5: =IF(COUNTIF($A$2:$A$150,A5)>1,"Duplicate","Unique") -> Unique | J5: =IF(OR(F5<=0,F5>100),"Error:Check Data","Valid") -> Valid
A6: P-2026-05 | B6: HBA1C | C6: Biochemistry | D6: Routine | E6: Serum | F6: 5 | G6: =VLOOKUP(C6,Master_Targets!$A$2:$B$5,2,0) -> 6 | H6: =IF(F6>G6,"Delayed","On-Time") -> On-Time | I6: =IF(COUNTIF($A$2:$A$150,A6)>1,"Duplicate","Unique") -> Unique | J6: =IF(OR(F5<=0,F6>100),"Error:Check Data","Valid") -> Valid
A7: P-2026-06 | B7: CSF Analysis | C7: Microbiology | D7: Stat | E7: CSF Fluid | F7: 8 | G7: =VLOOKUP(C7,Master_Targets!$A$2:$B$5,2,0) -> 48 | H7: =IF(F7>G7,"Delayed","On-Time") -> On-Time | I7: =IF(COUNTIF($A$2:$A$150,A7)>1,"Duplicate","Unique") -> Unique | J7: =IF(OR(F7<=0,F7>100),"Error:Check Data","Valid") -> Valid
A8: P-2026-07 | B8: RT-PCR (Respiratory Panel) | C8: Molecular | D8: Stat | E8: Nasopharyngeal Swab | F8: 12 | G8: =VLOOKUP(C8,Master_Targets!$A$2:$B$5,2,0) -> 12 | H8: =IF(F8>G8,"Delayed","On-Time") -> On-Time | I8: =IF(COUNTIF($A$2:$A$150,A8)>1,"Duplicate","Unique") -> Unique | J8: =IF(OR(F8<=0,F8>100),"Error:Check Data","Valid") -> Valid
A9: P-2026-08 | B9: Stool Culture | C9: Microbiology | D9: Routine | E9: Stool | F9: 52 | G9: =VLOOKUP(C9,Master_Targets!$A$2:$B$5,2,0) -> 48 | H9: =IF(F9>G9,"Delayed","On-Time") -> Delayed | I9: =IF(COUNTIF($A$2:$A$150,A9)>1,"Duplicate","Unique") -> Unique | J9: =IF(OR(F8<=0,F9>100),"Error:Check Data","Valid") -> Valid
A10: P-2026-09 | B10: Liver Function Test (LFT) | C10: Biochemistry | D10: Stat | E10: Serum | F10: 3 | G10: =VLOOKUP(C10,Master_Targets!$A$2:$B$5,2,0) -> 6 | H10: =IF(F10>G10,"Delayed","On-Time") -> On-Time | I10: =IF(COUNTIF($A$2:$A$150,A10)>1,"Duplicate","Unique") -> Unique | J10: =IF(OR(F10<=0,F10>100),"Error:Check Data","Valid") -> Valid
A11: P-2026-10 | B11: Wound Swab Gram Stain | C11: Microbiology | D11: Stat | E11: Pus Swab | F11: 2 | G11: =VLOOKUP(C11,Master_Targets!$A$2:$B$5,2,0) -> 48 | H11: =IF(F11>G11,"Delayed","On-Time") -> On-Time | I11: =IF(COUNTIF($A$2:$A$150,A11)>1,"Duplicate","Unique") -> Unique | J11: =IF(OR(F11<=0,F11>100),"Error:Check Data","Valid") -> Valid
A12: Patient_ID | B12: Blood Culture and Sensitivity | C12: Microbiology | D12: Stat | E12: Whole Blood | F12: 36 | G12: =VLOOKUP(C12,Master_Targets!$A$2:$B$5,2,0) -> 48 | H12: =IF(F12>G12,"Delayed","On-Time") -> On-Time | I12: =IF(COUNTIF($A$2:$A$150,A12)>1,"Duplicate","Unique") -> Duplicate | J12: =IF(OR(F11<=0,F12>100),"Error:Check Data","Valid") -> Valid
A13: P-2026-11 | B13: Urine Culture | C13: Microbiology | D13: Routine | E13: Urine | F13: 6 | G13: =VLOOKUP(C13,Master_Targets!$A$2:$B$5,2,0) -> 48 | H13: =IF(F13>G13,"Delayed","On-Time") -> On-Time | I13: =IF(COUNTIF($A$2:$A$150,A13)>1,"Duplicate","Unique") -> Unique | J13: =IF(OR(F13<=0,F13>100),"Error:Check Data","Valid") -> Valid
A14: P-2026-12 | B14: CBC (Complete Blod Count) | C14: Hematology | D14: Routine | E14: EDTA Blood | F14: 48 | G14: =VLOOKUP(C14,Master_Targets!$A$2:$B$5,2,0) -> 4 | H14: =IF(F14>G14,"Delayed","On-Time") -> Delayed | I14: =IF(COUNTIF($A$2:$A$150,A14)>1,"Duplicate","Unique") -> Unique | J14: =IF(OR(F14<=0,F14>100),"Error:Check Data","Valid") -> Valid
A15: P-2026-13 | B15: Sputum For AFB | C15: Microbiology | D15: Routine | E15: Sputum | F15: 52 | G15: =VLOOKUP(C15,Master_Targets!$A$2:$B$5,2,0) -> 48 | H15: =IF(F15>G15,"Delayed","On-Time") -> Delayed | I15: =IF(COUNTIF($A$2:$A$150,A15)>1,"Duplicate","Unique") -> Unique | J15: =IF(OR(F14<=0,F15>100),"Error:Check Data","Valid") -> Valid
A16: P-2026-14 | B16: HBA1C | C16: Biochemistry | D16: Routine | E16: Serum | F16: 9 | G16: =VLOOKUP(C16,Master_Targets!$A$2:$B$5,2,0) -> 6 | H16: =IF(F16>G16,"Delayed","On-Time") -> Delayed | I16: =IF(COUNTIF($A$2:$A$150,A16)>1,"Duplicate","Unique") -> Unique | J16: =IF(OR(F16<=0,F16>100),"Error:Check Data","Valid") -> Valid
A17: P-2026-15 | B17: CSF Analysis | C17: Microbiology | D17: Stat | E17: CSF Fluid | F17: 5 | G17: =VLOOKUP(C17,Master_Targets!$A$2:$B$5,2,0) -> 48 | H17: =IF(F17>G17,"Delayed","On-Time") -> On-Time | I17: =IF(COUNTIF($A$2:$A$150,A17)>1,"Duplicate","Unique") -> Unique | J17: =IF(OR(F17<=0,F17>100),"Error:Check Data","Valid") -> Valid
A18: P-2026-16 | B18: RT-PCR (Respiratory Panel) | C18: Molecular | D18: Stat | E18: Nasopharyngeal Swab | F18: 6 | G18: =VLOOKUP(C18,Master_Targets!$A$2:$B$5,2,0) -> 12 | H18: =IF(F18>G18,"Delayed","On-Time") -> On-Time | I18: =IF(COUNTIF($A$2:$A$150,A18)>1,"Duplicate","Unique") -> Unique | J18: =IF(OR(F17<=0,F18>100),"Error:Check Data","Valid") -> Valid
A19: P-2026-17 | B19: Stool Culture | C19: Microbiology | D19: Routine | E19: Stool | F19: 8 | G19: =VLOOKUP(C19,Master_Targets!$A$2:$B$5,2,0) -> 48 | H19: =IF(F19>G19,"Delayed","On-Time") -> On-Time | I19: =IF(COUNTIF($A$2:$A$150,A19)>1,"Duplicate","Unique") -> Unique | J19: =IF(OR(F19<=0,F19>100),"Error:Check Data","Valid") -> Valid
A20: P-2026-18 | B20: Liver Function Test (LFT) | C20: Biochemistry | D20: Stat | E20: Serum | F20: 47 | G20: =VLOOKUP(C20,Master_Targets!$A$2:$B$5,2,0) -> 6 | H20: =IF(F20>G20,"Delayed","On-Time") -> Delayed | I20: =IF(COUNTIF($A$2:$A$150,A20)>1,"Duplicate","Unique") -> Unique | J20: =IF(OR(F20<=0,F20>100),"Error:Check Data","Valid") -> Valid
A21: P-2026-19 | B21: Wound Swab Gram Stain | C21: Microbiology | D21: Stat | E21: Pus Swab | F21: 23 | G21: =VLOOKUP(C21,Master_Targets!$A$2:$B$5,2,0) -> 48 | H21: =IF(F21>G21,"Delayed","On-Time") -> On-Time | I21: =IF(COUNTIF($A$2:$A$150,A21)>1,"Duplicate","Unique") -> Unique | J21: =IF(OR(F20<=0,F21>100),"Error:Check Data","Valid") -> Valid
A22: P-2026-20 | B22: Blood Culture and Sensitivity | C22: Microbiology | D22: Stat | E22: Whole Blood | F22: 24 | G22: =VLOOKUP(C22,Master_Targets!$A$2:$B$5,2,0) -> 48 | H22: =IF(F22>G22,"Delayed","On-Time") -> On-Time | I22: =IF(COUNTIF($A$2:$A$150,A22)>1,"Duplicate","Unique") -> Unique | J22: =IF(OR(F22<=0,F22>100),"Error:Check Data","Valid") -> Valid
A23: Patient_ID | B23: Urine Culture | C23: Microbiology | D23: Routine | E23: Urine | F23: 12 | G23: =VLOOKUP(C23,Master_Targets!$A$2:$B$5,2,0) -> 48 | H23: =IF(F23>G23,"Delayed","On-Time") -> On-Time | I23: =IF(COUNTIF($A$2:$A$150,A23)>1,"Duplicate","Unique") -> Duplicate | J23: =IF(OR(F23<=0,F23>100),"Error:Check Data","Valid") -> Valid
A24: P-2026-21 | B24: CBC (Complete Blod Count) | C24: Hematology | D24: Routine | E24: EDTA Blood | F24: 52 | G24: =VLOOKUP(C24,Master_Targets!$A$2:$B$5,2,0) -> 4 | H24: =IF(F24>G24,"Delayed","On-Time") -> Delayed | I24: =IF(COUNTIF($A$2:$A$150,A24)>1,"Duplicate","Unique") -> Unique | J24: =IF(OR(F23<=0,F24>100),"Error:Check Data","Valid") -> Valid
A25: P-2026-22 | B25: Sputum For AFB | C25: Microbiology | D25: Routine | E25: Sputum | F25: 7 | G25: =VLOOKUP(C25,Master_Targets!$A$2:$B$5,2,0) -> 48 | H25: =IF(F25>G25,"Delayed","On-Time") -> On-Time | I25: =IF(COUNTIF($A$2:$A$150,A25)>1,"Duplicate","Unique") -> Unique | J25: =IF(OR(F25<=0,F25>100),"Error:Check Data","Valid") -> Valid
A26: P-2026-23 | B26: HBA1C | C26: Biochemistry | D26: Routine | E26: Serum | F26: 3 | G26: =VLOOKUP(C26,Master_Targets!$A$2:$B$5,2,0) -> 6 | H26: =IF(F26>G26,"Delayed","On-Time") -> On-Time | I26: =IF(COUNTIF($A$2:$A$150,A26)>1,"Duplicate","Unique") -> Unique | J26: =IF(OR(F26<=0,F26>100),"Error:Check Data","Valid") -> Valid
A27: P-2026-24 | B27: CSF Analysis | C27: Microbiology | D27: Stat | E27: CSF Fluid | F27: 2 | G27: =VLOOKUP(C27,Master_Targets!$A$2:$B$5,2,0) -> 48 | H27: =IF(F27>G27,"Delayed","On-Time") -> On-Time | I27: =IF(COUNTIF($A$2:$A$150,A27)>1,"Duplicate","Unique") -> Unique | J27: =IF(OR(F26<=0,F27>100),"Error:Check Data","Valid") -> Valid
A28: P-2026-25 | B28: RT-PCR (Respiratory Panel) | C28: Molecular | D28: Stat | E28: Nasopharyngeal Swab | F28: 32 | G28: =VLOOKUP(C28,Master_Targets!$A$2:$B$5,2,0) -> 12 | H28: =IF(F28>G28,"Delayed","On-Time") -> Delayed | I28: =IF(COUNTIF($A$2:$A$150,A28)>1,"Duplicate","Unique") -> Unique | J28: =IF(OR(F28<=0,F28>100),"Error:Check Data","Valid") -> Valid
A29: P-2026-26 | B29: Stool Culture | C29: Microbiology | D29: Routine | E29: Stool | F29: 4 | G29: =VLOOKUP(C29,Master_Targets!$A$2:$B$5,2,0) -> 48 | H29: =IF(F29>G29,"Delayed","On-Time") -> On-Time | I29: =IF(COUNTIF($A$2:$A$150,A29)>1,"Duplicate","Unique") -> Unique | J29: =IF(OR(F29<=0,F29>100),"Error:Check Data","Valid") -> Valid
A30: P-2026-27 | B30: Liver Function Test (LFT) | C30: Biochemistry | D30: Stat | E30: Serum | F30: 5 | G30: =VLOOKUP(C30,Master_Targets!$A$2:$B$5,2,0) -> 6 | H30: =IF(F30>G30,"Delayed","On-Time") -> On-Time | I30: =IF(COUNTIF($A$2:$A$150,A30)>1,"Duplicate","Unique") -> Unique | J30: =IF(OR(F29<=0,F30>100),"Error:Check Data","Valid") -> Valid
A31: P-2026-28 | B31: Wound Swab Gram Stain | C31: Microbiology | D31: Stat | E31: Pus Swab | F31: 6 | G31: =VLOOKUP(C31,Master_Targets!$A$2:$B$5,2,0) -> 48 | H31: =IF(F31>G31,"Delayed","On-Time") -> On-Time | I31: =IF(COUNTIF($A$2:$A$150,A31)>1,"Duplicate","Unique") -> Unique | J31: =IF(OR(F31<=0,F31>100),"Error:Check Data","Valid") -> Valid
A32: P-2026-29 | B32: Blood Culture and Sensitivity | C32: Microbiology | D32: Stat | E32: Whole Blood | F32: 7 | G32: =VLOOKUP(C32,Master_Targets!$A$2:$B$5,2,0) -> 48 | H32: =IF(F32>G32,"Delayed","On-Time") -> On-Time | I32: =IF(COUNTIF($A$2:$A$150,A32)>1,"Duplicate","Unique") -> Unique | J32: =IF(OR(F32<=0,F32>100),"Error:Check Data","Valid") -> Valid
A33: P-2026-30 | B33: Urine Culture | C33: Microbiology | D33: Routine | E33: Urine | F33: 38 | G33: =VLOOKUP(C33,Master_Targets!$A$2:$B$5,2,0) -> 48 | H33: =IF(F33>G33,"Delayed","On-Time") -> On-Time | I33: =IF(COUNTIF($A$2:$A$150,A33)>1,"Duplicate","Unique") -> Unique | J33: =IF(OR(F32<=0,F33>100),"Error:Check Data","Valid") -> Valid
A34: Patient_ID | B34: CBC (Complete Blod Count) | C34: Hematology | D34: Routine | E34: EDTA Blood | F34: 25 | G34: =VLOOKUP(C34,Master_Targets!$A$2:$B$5,2,0) -> 4 | H34: =IF(F34>G34,"Delayed","On-Time") -> Delayed | I34: =IF(COUNTIF($A$2:$A$150,A34)>1,"Duplicate","Unique") -> Duplicate | J34: =IF(OR(F34<=0,F34>100),"Error:Check Data","Valid") -> Valid
A35: P-2026-31 | B35: Sputum For AFB | C35: Microbiology | D35: Routine | E35: Sputum | F35: 24 | G35: =VLOOKUP(C35,Master_Targets!$A$2:$B$5,2,0) -> 48 | H35: =IF(F35>G35,"Delayed","On-Time") -> On-Time | I35: =IF(COUNTIF($A$2:$A$150,A35)>1,"Duplicate","Unique") -> Unique | J35: =IF(OR(F35<=0,F35>100),"Error:Check Data","Valid") -> Valid
A36: P-2026-32 | B36: HBA1C | C36: Biochemistry | D36: Routine | E36: Serum | F36: 8 | G36: =VLOOKUP(C36,Master_Targets!$A$2:$B$5,2,0) -> 6 | H36: =IF(F36>G36,"Delayed","On-Time") -> Delayed | I36: =IF(COUNTIF($A$2:$A$150,A36)>1,"Duplicate","Unique") -> Unique | J36: =IF(OR(F35<=0,F36>100),"Error:Check Data","Valid") -> Valid
A37: P-2026-33 | B37: CSF Analysis | C37: Microbiology | D37: Stat | E37: CSF Fluid | F37: 6 | G37: =VLOOKUP(C37,Master_Targets!$A$2:$B$5,2,0) -> 48 | H37: =IF(F37>G37,"Delayed","On-Time") -> On-Time | I37: =IF(COUNTIF($A$2:$A$150,A37)>1,"Duplicate","Unique") -> Unique | J37: =IF(OR(F37<=0,F37>100),"Error:Check Data","Valid") -> Valid
A38: P-2026-34 | B38: RT-PCR (Respiratory Panel) | C38: Molecular | D38: Stat | E38: Nasopharyngeal Swab | F38: 5 | G38: =VLOOKUP(C38,Master_Targets!$A$2:$B$5,2,0) -> 12 | H38: =IF(F38>G38,"Delayed","On-Time") -> On-Time | I38: =IF(COUNTIF($A$2:$A$150,A38)>1,"Duplicate","Unique") -> Unique | J38: =IF(OR(F38<=0,F38>100),"Error:Check Data","Valid") -> Valid
A39: P-2026-35 | B39: Stool Culture | C39: Microbiology | D39: Routine | E39: Stool | F39: 8 | G39: =VLOOKUP(C39,Master_Targets!$A$2:$B$5,2,0) -> 48 | H39: =IF(F39>G39,"Delayed","On-Time") -> On-Time | I39: =IF(COUNTIF($A$2:$A$150,A39)>1,"Duplicate","Unique") -> Unique | J39: =IF(OR(F38<=0,F39>100),"Error:Check Data","Valid") -> Valid
A40: P-2026-36 | B40: Liver Function Test (LFT) | C40: Biochemistry | D40: Stat | E40: Serum | F40: 48 | G40: =VLOOKUP(C40,Master_Targets!$A$2:$B$5,2,0) -> 6 | H40: =IF(F40>G40,"Delayed","On-Time") -> Delayed | I40: =IF(COUNTIF($A$2:$A$150,A40)>1,"Duplicate","Unique") -> Unique | J40: =IF(OR(F40<=0,F40>100),"Error:Check Data","Valid") -> Valid
...

Sheet Master_Targets
A1: Department | B1: Standard_Target_Hours
A2: Microbiology | B2: 48
A3: Hematology | B3: 4
A4: Biochemistry | B4: 6
A5: Molecular | B5: 12

Sheet Analysis_KPI
A1: Department | B1: Total_Actual_Hours | C1: Average_Actual_Hours | D1: Total_Test_Counts
A2: Microbiology | B2: =SUMIFS(Lab_Diagnostics_TAT_Project!$F$2:$F$150,Lab_Diagnostics_TAT_Project!$C$2:$C$150,A2) -> 1734 | C2: =AVERAGEIFS(Lab_Diagnostics_TAT_Project!$F$2:$F$150,Lab_Diagnostics_TAT_Project!$C$2:$C$150,A2) -> 19.483146 | D2: =COUNTIFS(Lab_Diagnostics_TAT_Project!$C$2:$C$150,A2) -> 89
A3: Hematology | B3: =SUMIFS(Lab_Diagnostics_TAT_Project!$F$2:$F$150,Lab_Diagnostics_TAT_Project!$C$2:$C$150,A3) -> 384 | C3: =AVERAGEIFS(Lab_Diagnostics_TAT_Project!$F$2:$F$150,Lab_Diagnostics_TAT_Project!$C$2:$C$150,A3) -> 25.6 | D3: =COUNTIFS(Lab_Diagnostics_TAT_Project!$C$2:$C$150,A3) -> 15
A4: Biochemistry | B4: =SUMIFS(Lab_Diagnostics_TAT_Project!$F$2:$F$150,Lab_Diagnostics_TAT_Project!$C$2:$C$150,A4) -> 631 | C4: =AVERAGEIFS(Lab_Diagnostics_TAT_Project!$F$2:$F$150,Lab_Diagnostics_TAT_Project!$C$2:$C$150,A4) -> 21.033333 | D4: =COUNTIFS(Lab_Diagnostics_TAT_Project!$C$2:$C$150,A4) -> 30
A5: Molecular | B5: =SUMIFS(Lab_Diagnostics_TAT_Project!$F$2:$F$150,Lab_Diagnostics_TAT_Project!$C$2:$C$150,A5) -> 287 | C5: =AVERAGEIFS(Lab_Diagnostics_TAT_Project!$F$2:$F$150,Lab_Diagnostics_TAT_Project!$C$2:$C$150,A5) -> 19.133333 | D5: =COUNTIFS(Lab_Diagnostics_TAT_Project!$C$2:$C$150,A5) -> 15

Sheet Pivot Analysis
A3: Row Labels | B3: Max of Actual_TAT_Hours | C3: Min of Actual_TAT_Hours2
A4: Biochemistry | B4: 48 | C4: 3
A5: Hematology | B5: 52 | C5: 3
A6: Microbiology | B6: 52 | C6: 2
A7: Molecular | B7: 43 | C7: 3
A8: (blank)
A9: Grand Total | B9: 52 | C9: 2
